Workbook

Sheet 監視項目一覧
A1: No. | B1: カテゴリ(ルールグループ) | C1: 対象コンポーネント | D1: アラート名 | E1: 重要度 (severity) | F1: 監視内容 | G1: 発報条件・閾値 | H1: 継続時間 (for) | I1: 追加ラベル | J1: Summary(原文) | K1: Description(原文) | L1: PromQL(expr) | M1: Runbook URL | N1: 備考
A2: 1 | B2: alertmanager.rules | C2: Alertmanager | D2: AlertmanagerFailedReload | E2: critical | F2: Alertmanager の設定リロード成否 | G2: 直近 5 分間の設定リロードが一度も成功していない(alertmanager_config_last_reload_successful == 0) | H2: 10m(10分) | J2: Reloading an Alertmanager configuration has failed. | K2: Configuration has failed to load for {{ $labels.namespace }}/{{ $labels.pod}}. | L2: # Without max_over_time, failed scrapes could create false negatives, see # https://www.robustperception.io/alerting-on-gauges-in-prometheus-2-0 for details. max_over_time(alertmanager_config_last_reload_successful{job="monitoring-kube-prometheus-alertmanager",container="alertmanager",namespace="monitoring"}[5m]) == 0 | M2: https://runbooks.prometheus-operator.dev/runbooks/alertmanager/alertmanagerfailedreload
A3: 2 | B3: alertmanager.rules | C3: Alertmanager | D3: AlertmanagerMembersInconsistent | E3: critical | F3: Alertmanager クラスタのメンバー認識数 | G3: 各インスタンスが認識しているクラスタメンバー数が、実際のインスタンス数より少ない | H3: 15m(15分) | J3: A member of an Alertmanager cluster has not found all other cluster members. | K3: Alertmanager {{ $labels.namespace }}/{{ $labels.pod}} has only found {{ $value }} members of the {{$labels.job}} cluster. | L3: # Without max_over_time, failed scrapes could create false negatives, see # https://www.robustperception.io/alerting-on-gauges-in-prometheus-2-0 for details. max_over_time(alertmanager_cluster_members{job="monitoring-kube-prometheus-alertmanager",container="alertmanager",namespace="monitoring"}[5m]) < on (namespace,service,cluster) group_left count by (namespace,service,cluster) (max_over_time(alertmanager_cluster_members{job="monitoring-kube-prometheus-alertmanager",container="alertmanager",namespace="monitoring"}[5m])) | M3: https://runbooks.prometheus-operator.dev/runbooks/alertmanager/alertmanagermembersinconsistent
A4: 3 | B4: alertmanager.rules | C4: Alertmanager | D4: AlertmanagerFailedToSendAlerts | E4: warning | F4: Alertmanager インスタンス単位の通知送信失敗率 | G4: 直近 15 分間の通知送信失敗率が 1% を超過(インテグレーション別) | H4: 5m(5分) | J4: An Alertmanager instance failed to send notifications. | K4: Alertmanager {{ $labels.namespace }}/{{ $labels.pod}} failed to send {{ $value | humanizePercentage }} of notifications to {{ $labels.integration }}. | L4: ( rate(alertmanager_notifications_failed_total{job="monitoring-kube-prometheus-alertmanager",container="alertmanager",namespace="monitoring"}[15m]) / ignoring (reason) group_left rate(alertmanager_notifications_total{job="monitoring-kube-prometheus-alertmanager",container="alertmanager",namespace="monitoring"}[15m]) ) > 0.01 | M4: https://runbooks.prometheus-operator.dev/runbooks/alertmanager/alertmanagerfailedtosendalerts
A5: 4 | B5: alertmanager.rules | C5: Alertmanager | D5: AlertmanagerClusterFailedToSendAlerts | E5: critical | F5: Alertmanager クラスタ全体の通知送信失敗率(重要インテグレーション) | G5: クラスタ内の全インスタンスで、直近 15 分間の通知送信失敗率の最小値が 1% を超過 | H5: 5m(5分) | J5: All Alertmanager instances in a cluster failed to send notifications to a critical integration. | K5: The minimum notification failure rate to {{ $labels.integration }} sent from any instance in the {{$labels.job}} cluster is {{ $value | humanizePercentage }}. | L5: min by (namespace,service, integration) ( rate(alertmanager_notifications_failed_total{job="monitoring-kube-prometheus-alertmanager",container="alertmanager",namespace="monitoring", integration=~`.*`}[15m]) / ignoring (reason) group_left rate(alertmanager_notifications_total{job="monitoring-kube-prometheus-alertmanager",container="alertmanager",namespace="monitoring", integration=~`.*`}[15m]) > 0 ) > 0.01 | M5: https://runbooks.prometheus-operator.dev/runbooks/alertmanager/alertmanagerclusterfailedtosendalerts | N5: 本環境では integration=~`.*` のため全インテグレーションが本条件に該当する。同名アラートが複数段階(severity 別)で定義されている。
A6: 5 | B6: alertmanager.rules | C6: Alertmanager | D6: AlertmanagerClusterFailedToSendAlerts | E6: warning | F6: Alertmanager クラスタ全体の通知送信失敗率(非重要インテグレーション) | G6: クラスタ内の全インスタンスで、直近 15 分間の通知送信失敗率の最小値が 1% を超過 | H6: 5m(5分) | J6: All Alertmanager instances in a cluster failed to send notifications to a non-critical integration. | K6: The minimum notification failure rate to {{ $labels.integration }} sent from any instance in the {{$labels.job}} cluster is {{ $value | humanizePercentage }}. | L6: min by (namespace,service, integration) ( rate(alertmanager_notifications_failed_total{job="monitoring-kube-prometheus-alertmanager",container="alertmanager",namespace="monitoring", integration!~`.*`}[15m]) / ignoring (reason) group_left rate(alertmanager_notifications_total{job="monitoring-kube-prometheus-alertmanager",container="alertmanager",namespace="monitoring", integration!~`.*`}[15m]) > 0 ) > 0.01 | M6: https://runbooks.prometheus-operator.dev/runbooks/alertmanager/alertmanagerclusterfailedtosendalerts | N6: 本環境では integration!~`.*` のため対象インテグレーションは存在せず、実質発報しない。同名アラートが複数段階(severity 別)で定義されている。
A7: 6 | B7: alertmanager.rules | C7: Alertmanager | D7: AlertmanagerConfigInconsistent | E7: critical | F7: Alertmanager クラスタ内の設定一致性 | G7: 同一クラスタ内のインスタンス間で設定ハッシュが 2 種類以上存在する(設定不一致) | H7: 20m(20分) | J7: Alertmanager instances within the same cluster have different configurations. | K7: Alertmanager instances within the {{$labels.job}} cluster have different configurations. | L7: count by (namespace,service,cluster) ( count_values by (namespace,service,cluster) ("config_hash", alertmanager_config_hash{job="monitoring-kube-prometheus-alertmanager",container="alertmanager",namespace="monitoring"}) ) != 1 | M7: https://runbooks.prometheus-operator.dev/runbooks/alertmanager/alertmanagerconfiginconsistent
A8: 7 | B8: alertmanager.rules | C8: Alertmanager | D8: AlertmanagerClusterDown | E8: critical | F8: Alertmanager クラスタの稼働インスタンス数 | G8: 直近 5 分間の平均稼働率(up)が 0.5 未満のインスタンスが、クラスタの半数以上 | H8: 5m(5分) | J8: Half or more of the Alertmanager instances within the same cluster are down. | K8: {{ $value | humanizePercentage }} of Alertmanager instances within the {{$labels.job}} cluster have been up for less than half of the last 5m. | L8: ( count by (namespace,service,cluster) ( avg_over_time(up{job="monitoring-kube-prometheus-alertmanager",container="alertmanager",namespace="monitoring"}[5m]) < 0.5 ) / count by (namespace,service,cluster) ( up{job="monitoring-kube-prometheus-alertmanager",container="alertmanager",namespace="monitoring"} ) ) >= 0.5 | M8: https://runbooks.prometheus-operator.dev/runbooks/alertmanager/alertmanagerclusterdown
A9: 8 | B9: alertmanager.rules | C9: Alertmanager | D9: AlertmanagerClusterCrashlooping | E9: critical | F9: Alertmanager クラスタのクラッシュループ | G9: 直近 10 分間にプロセス再起動が 4 回を超えたインスタンスが、クラスタの半数以上 | H9: 5m(5分) | J9: Half or more of the Alertmanager instances within the same cluster are crashlooping. | K9: {{ $value | humanizePercentage }} of Alertmanager instances within the {{$labels.job}} cluster have restarted at least 5 times in the last 10m. | L9: ( count by (namespace,service,cluster) ( changes(process_start_time_seconds{job="monitoring-kube-prometheus-alertmanager",container="alertmanager",namespace="monitoring"}[10m]) > 4 ) / count by (namespace,service,cluster) ( up{job="monitoring-kube-prometheus-alertmanager",container="alertmanager",namespace="monitoring"} ) ) >= 0.5 | M9: https://runbooks.prometheus-operator.dev/runbooks/alertmanager/alertmanagerclustercrashlooping
A10: 9 | B10: alertmanager.rules | C10: Alertmanager | D10: AlertmanagerClusterFailedPeers | E10: warning | F10: Alertmanager クラスタのピア接続失敗 | G10: 直近 5 分間で接続に失敗しているピア数が 0 より大きい | H10: 15m(15分) | J10: An Alertmanager instance has failed peers in the cluster. | K10: Alertmanager {{ $labels.namespace }}/{{ $labels.pod}} has {{ $value }} failed peers in the {{$labels.job}} cluster. | L10: # Without max_over_time, failed scrapes could create false negatives, see # https://www.robustperception.io/alerting-on-gauges-in-prometheus-2-0 for details. max_over_time(alertmanager_cluster_failed_peers{job="monitoring-kube-prometheus-alertmanager",container="alertmanager",namespace="monitoring"}[5m]) > 0 | M10: https://runbooks.prometheus-operator.dev/runbooks/alertmanager/alertmanagerclusterfailedpeers
A11: 10 | B11: config-reloaders | C11: Prometheus Operator(config-reloader) | D11: ConfigReloaderSidecarErrors | E11: warning | F11: config-reloader サイドカーの設定リロード成否 | G11: 直近 5 分間の設定リロードが一度も成功していない(reloader_last_reload_successful == 0) | H11: 10m(10分) | J11: config-reloader sidecar has not had a successful reload for 10m | K11: Errors encountered while the {{$labels.pod}} config-reloader sidecar attempts to sync config in {{$labels.namespace}} namespace. As a result, configuration for service running in {{$labels.pod}} may be stale and cannot be updated anymore. | L11: max_over_time(reloader_last_reload_successful{namespace=~".+"}[5m]) == 0 | M11: https://runbooks.prometheus-operator.dev/runbooks/prometheus-operator/configreloadersidecarerrors
A12: 11 | B12: etcd | C12: etcd | D12: etcdMembersDown | E12: warning | F12: etcd メンバーの稼働状況 | G12: up == 0 のメンバーが存在する、または直近 120 秒間のピア送信失敗レートが 0.01/秒 を超過 | H12: 20m(20分) | J12: etcd cluster members are down. | K12: etcd cluster "{{ $labels.job }}": members are down ({{ $value }}). | L12: max without (endpoint) ( sum without (instance, pod) (up{job=~".*etcd.*"} == bool 0) or count without (To) ( sum without (instance, pod) (rate(etcd_network_peer_sent_failures_total{job=~".*etcd.*"}[120s])) > 0.01 ) ) > 0 | M12: https://runbooks.prometheus-operator.dev/runbooks/etcd/etcdmembersdown
A13: 12 | B13: etcd | C13: etcd | D13: etcdInsufficientMembers | E13: critical | F13: etcd クラスタの過半数(quorum)維持 | G13: 稼働中(up == 1)のメンバー数が (総メンバー数 + 1) / 2 未満(quorum 喪失) | H13: 3m(3分) | J13: etcd cluster has insufficient number of members. | K13: etcd cluster "{{ $labels.job }}": insufficient members ({{ $value }}). | L13: sum(up{job=~".*etcd.*"} == bool 1) without (instance, pod) < ((count(up{job=~".*etcd.*"}) without (instance, pod) + 1) / 2) | M13: https://runbooks.prometheus-operator.dev/runbooks/etcd/etcdinsufficientmembers
A14: 13 | B14: etcd | C14: etcd | D14: etcdNoLeader | E14: critical | F14: etcd リーダーの有無 | G14: etcd_server_has_leader == 0(リーダー不在) | H14: 1m(1分) | J14: etcd cluster has no leader. | K14: etcd cluster "{{ $labels.job }}": member {{ $labels.instance }} has no leader. | L14: etcd_server_has_leader{job=~".*etcd.*"} == 0 | M14: https://runbooks.prometheus-operator.dev/runbooks/etcd/etcdnoleader
A15: 14 | B15: etcd | C15: etcd | D15: etcdHighNumberOfLeaderChanges | E15: warning | F15: etcd リーダー交代回数 | G15: 直近 15 分間のリーダー交代回数が 4 回以上 | H15: 5m(5分) | J15: etcd cluster has high number of leader changes. | K15: etcd cluster "{{ $labels.job }}": {{ $value }} leader changes within the last 15 minutes. Frequent elections may be a sign of insufficient resources, high network latency, or disruptions by other components and should be investigated. | L15: increase((max without (instance, pod) (etcd_server_leader_changes_seen_total{job=~".*etcd.*"}) or 0*absent(etcd_server_leader_changes_seen_total{job=~".*etcd.*"}))[15m:1m]) >= 4 | M15: https://runbooks.prometheus-operator.dev/runbooks/etcd/etcdhighnumberofleaderchanges
A16: 15 | B16: etcd | C16: etcd | D16: etcdHighNumberOfFailedGRPCRequests | E16: warning | F16: etcd gRPC リクエスト失敗率 | G16: 直近 5 分間の gRPC 失敗率(Unknown/Unavailable/DeadlineExceeded 等)が 1% を超過 | H16: 10m(10分) | J16: etcd cluster has high number of failed grpc requests. | K16: etcd cluster "{{ $labels.job }}": {{ $value }}% of requests for {{ $labels.grpc_method }} failed on etcd instance {{ $labels.instance }}. | L16: 100 * sum(rate(grpc_server_handled_total{job=~".*etcd.*", grpc_code=~"Unknown|FailedPrecondition|ResourceExhausted|Internal|Unavailable|DataLoss|DeadlineExceeded"}[5m])) without (grpc_type, grpc_code) / sum(rate(grpc_server_handled_total{job=~".*etcd.*"}[5m])) without (grpc_type, grpc_code) > 1 | M16: https://runbooks.prometheus-operator.dev/runbooks/etcd/etcdhighnumberoffailedgrpcrequests | N16: 同名アラートが複数段階(severity 別)で定義されている。
A17: 16 | B17: etcd | C17: etcd | D17: etcdHighNumberOfFailedGRPCRequests | E17: critical | F17: etcd gRPC リクエスト失敗率 | G17: 直近 5 分間の gRPC 失敗率(Unknown/Unavailable/DeadlineExceeded 等)が 5% を超過 | H17: 5m(5分) | J17: etcd cluster has high number of failed grpc requests. | K17: etcd cluster "{{ $labels.job }}": {{ $value }}% of requests for {{ $labels.grpc_method }} failed on etcd instance {{ $labels.instance }}. | L17: 100 * sum(rate(grpc_server_handled_total{job=~".*etcd.*", grpc_code=~"Unknown|FailedPrecondition|ResourceExhausted|Internal|Unavailable|DataLoss|DeadlineExceeded"}[5m])) without (grpc_type, grpc_code) / sum(rate(grpc_server_handled_total{job=~".*etcd.*"}[5m])) without (grpc_type, grpc_code) > 5 | M17: https://runbooks.prometheus-operator.dev/runbooks/etcd/etcdhighnumberoffailedgrpcrequests | N17: 同名アラートが複数段階(severity 別)で定義されている。
A18: 17 | B18: etcd | C18: etcd | D18: etcdGRPCRequestsSlow | E18: critical | F18: etcd gRPC 応答時間 | G18: 直近 5 分間の unary gRPC 処理時間の 99 パーセンタイルが 0.15 秒を超過(Defragment を除く) | H18: 10m(10分) | J18: etcd grpc requests are slow | K18: etcd cluster "{{ $labels.job }}": 99th percentile of gRPC requests is {{ $value }}s on etcd instance {{ $labels.instance }} for {{ $labels.grpc_method }} method. | L18: histogram_quantile(0.99, sum(rate(grpc_server_handling_seconds_bucket{job=~".*etcd.*", grpc_method!="Defragment", grpc_type="unary"}[5m])) without(grpc_type)) > 0.15 | M18: https://runbooks.prometheus-operator.dev/runbooks/etcd/etcdgrpcrequestsslow
A19: 18 | B19: etcd | C19: etcd | D19: etcdMemberCommunicationSlow | E19: warning | F19: etcd メンバー間通信の遅延 | G19: 直近 5 分間のピア間ラウンドトリップ時間の 99 パーセンタイルが 0.15 秒を超過 | H19: 10m(10分) | J19: etcd cluster member communication is slow. | K19: etcd cluster "{{ $labels.job }}": member communication with {{ $labels.To }} is taking {{ $value }}s on etcd instance {{ $labels.instance }}. | L19: histogram_quantile(0.99, rate(etcd_network_peer_round_trip_time_seconds_bucket{job=~".*etcd.*"}[5m])) > 0.15 | M19: https://runbooks.prometheus-operator.dev/runbooks/etcd/etcdmembercommunicationslow
A20: 19 | B20: etcd | C20: etcd | D20: etcdHighNumberOfFailedProposals | E20: warning | F20: etcd 提案(proposal)失敗数 | G20: 直近 15 分間の提案失敗レートが 5 件/秒 を超過 | H20: 15m(15分) | J20: etcd cluster has high number of proposal failures. | K20: etcd cluster "{{ $labels.job }}": {{ $value }} proposal failures within the last 30 minutes on etcd instance {{ $labels.instance }}. | L20: rate(etcd_server_proposals_failed_total{job=~".*etcd.*"}[15m]) > 5 | M20: https://runbooks.prometheus-operator.dev/runbooks/etcd/etcdhighnumberoffailedproposals
A21: 20 | B21: etcd | C21: etcd | D21: etcdHighFsyncDurations | E21: warning | F21: etcd WAL fsync 時間 | G21: 直近 5 分間の WAL fsync 時間の 99 パーセンタイルが 0.5 秒を超過 | H21: 10m(10分) | J21: etcd cluster 99th percentile fsync durations are too high. | K21: etcd cluster "{{ $labels.job }}": 99th percentile fsync durations are {{ $value }}s on etcd instance {{ $labels.instance }}. | L21: histogram_quantile(0.99, rate(etcd_disk_wal_fsync_duration_seconds_bucket{job=~".*etcd.*"}[5m])) > 0.5 | M21: https://runbooks.prometheus-operator.dev/runbooks/etcd/etcdhighfsyncdurations | N21: 同名アラートが複数段階(severity 別)で定義されている。
A22: 21 | B22: etcd | C22: etcd | D22: etcdHighFsyncDurations | E22: critical | F22: etcd WAL fsync 時間 | G22: 直近 5 分間の WAL fsync 時間の 99 パーセンタイルが 1 秒を超過 | H22: 10m(10分) | J22: etcd cluster 99th percentile fsync durations are too high. | K22: etcd cluster "{{ $labels.job }}": 99th percentile fsync durations are {{ $value }}s on etcd instance {{ $labels.instance }}. | L22: histogram_quantile(0.99, rate(etcd_disk_wal_fsync_duration_seconds_bucket{job=~".*etcd.*"}[5m])) > 1 | M22: https://runbooks.prometheus-operator.dev/runbooks/etcd/etcdhighfsyncdurations | N22: 同名アラートが複数段階(severity 別)で定義されている。
A23: 22 | B23: etcd | C23: etcd | D23: etcdHighCommitDurations | E23: warning | F23: etcd バックエンドコミット時間 | G23: 直近 5 分間のバックエンドコミット時間の 99 パーセンタイルが 0.25 秒を超過 | H23: 10m(10分) | J23: etcd cluster 99th percentile commit durations are too high. | K23: etcd cluster "{{ $labels.job }}": 99th percentile commit durations {{ $value }}s on etcd instance {{ $labels.instance }}. | L23: histogram_quantile(0.99, rate(etcd_disk_backend_commit_duration_seconds_bucket{job=~".*etcd.*"}[5m])) > 0.25 | M23: https://runbooks.prometheus-operator.dev/runbooks/etcd/etcdhighcommitdurations
A24: 23 | B24: etcd | C24: etcd | D24: etcdDatabaseQuotaLowSpace | E24: critical | F24: etcd DB サイズのクォータ使用率 | G24: DB 総サイズ / バックエンドクォータ が 95% を超過 | H24: 10m(10分) | J24: etcd cluster database is running full. | K24: etcd cluster "{{ $labels.job }}": database size exceeds the defined quota on etcd instance {{ $labels.instance }}, please defrag or increase the quota as the writes to etcd will be disabled when it is full. | L24: (last_over_time(etcd_mvcc_db_total_size_in_bytes{job=~".*etcd.*"}[5m]) / last_over_time(etcd_server_quota_backend_bytes{job=~".*etcd.*"}[5m]))*100 > 95 | M24: https://runbooks.prometheus-operator.dev/runbooks/etcd/etcddatabasequotalowspace
A25: 24 | B25: etcd | C25: etcd | D25: etcdExcessiveDatabaseGrowth | E25: warning | F25: etcd DB サイズの増加傾向 | G25: 直近 4 時間の傾向から 4 時間後の DB サイズを線形予測し、クォータを超過する見込み | H25: 10m(10分) | J25: etcd cluster database growing very fast. | K25: etcd cluster "{{ $labels.job }}": Predicting running out of disk space in the next four hours, based on write observations within the past four hours on etcd instance {{ $labels.instance }}, please check as it might be disruptive. | L25: predict_linear(etcd_mvcc_db_total_size_in_bytes{job=~".*etcd.*"}[4h], 4*60*60) > etcd_server_quota_backend_bytes{job=~".*etcd.*"} | M25: https://runbooks.prometheus-operator.dev/runbooks/etcd/etcdexcessivedatabasegrowth
A26: 25 | B26: etcd | C26: etcd | D26: etcdDatabaseHighFragmentationRatio | E26: warning | F26: etcd DB のフラグメンテーション | G26: 使用中サイズ / 総サイズ が 0.5 未満、かつ使用中サイズが 100MiB(104857600 バイト)を超過 | H26: 10m(10分) | J26: etcd database size in use is less than 50% of the actual allocated storage. | K26: etcd cluster "{{ $labels.job }}": database size in use on instance {{ $labels.instance }} is {{ $value | humanizePercentage }} of the actual allocated disk space, please run defragmentation (e.g. etcdctl defrag) to retrieve the unused fragmented disk space. | L26: (last_over_time(etcd_mvcc_db_total_size_in_use_in_bytes{job=~".*etcd.*"}[5m]) / last_over_time(etcd_mvcc_db_total_size_in_bytes{job=~".*etcd.*"}[5m])) < 0.5 and etcd_mvcc_db_total_size_in_use_in_bytes{job=~".*etcd.*"} > 104857600 | M26: https://runbooks.prometheus-operator.dev/runbooks/etcd/etcddatabasehighfragmentationratio | N26: defrag の実施を検討する。
A27: 26 | B27: general.rules | C27: 監視基盤(汎用) | D27: TargetDown | E27: warning | F27: スクレイプ対象(ターゲット)の到達性 | G27: job/namespace/service 単位で、到達不能(up == 0)なターゲットの割合が 10% を超過 | H27: 10m(10分) | J27: One or more targets are unreachable. | K27: {{ printf "%.4g" $value }}% of the {{ $labels.job }}/{{ $labels.service }} targets in {{ $labels.namespace }} namespace are down. | L27: 100 * (count(up == 0) BY (cluster, job, namespace, service) / count(up) BY (cluster, job, namespace, service)) > 10 | M27: https://runbooks.prometheus-operator.dev/runbooks/general/targetdown
A28: 27 | B28: general.rules | C28: 監視基盤(汎用) | D28: Watchdog | E28: none | F28: 監視パイプライン(Prometheus→Alertmanager)の生存確認 | G28: 常時発報(vector(1))。条件は常に真 | H28: 即時(for 未設定) | J28: An alert that should always be firing to certify that Alertmanager is working properly. | K28: This is an alert meant to ensure that the entire alerting pipeline is functional. This alert is always firing, therefore it should always be firing in Alertmanager and always fire against a receiver. There are integrations with various notification mechanisms that send a notification when this alert is not firing. For example the "DeadMansSnitch" integration in PagerDuty. | L28: vector(1) | M28: https://runbooks.prometheus-operator.dev/runbooks/general/watchdog | N28: 死活確認用アラート。Alertmanager では null receiver へルーティングし、通知しないのが標準構成。発報が止まった場合に監視基盤の異常と判断する(外部の Dead man's switch と組み合わせて使用)。for 未設定のため条件成立と同時に発報する。
A29: 28 | B29: general.rules | C29: 監視基盤(汎用) | D29: InfoInhibitor | E29: none | F29: info アラートの抑止(inhibit)制御 | G29: 同一 namespace で severity=info のアラートが firing、かつ warning/critical のアラートが firing していない | H29: 即時(for 未設定) | J29: Info-level alert inhibition. | K29: This is an alert that is used to inhibit info alerts. By themselves, the info-level alerts are sometimes very noisy, but they are relevant when combined with other alerts. This alert fires whenever there's a severity="info" alert, and stops firing when another alert with a severity of 'warning' or 'critical' starts firing on the same namespace. This alert should be routed to a null receiver and configured to inhibit alerts with severity="info". | L29: group by (namespace) (ALERTS{severity = "info"} == 1) unless on (namespace) group by (namespace) (ALERTS{alertname != "InfoInhibitor", alertstate = "firing", severity =~ "warning|critical"} == 1) | M29: https://runbooks.prometheus-operator.dev/runbooks/general/infoinhibitor | N29: 通知用ではなく inhibit_rules 用の補助アラート。Alertmanager では null receiver へルーティングし、本アラートが firing 中は同一 namespace の info アラートを抑止する構成が標準。for 未設定のため条件成立と同時に発報する。
A30: 29 | B30: kube-apiserver-slos | C30: kube-apiserver(SLO) | D30: KubeAPIErrorBudgetBurn | E30: critical | F30: kube-apiserver の可用性 SLO(99%)に対するエラーバジェット消費速度(バーンレート) | G30: 1 時間および 5 分のバーンレートが共に 14.4 倍(エラー率 14.4%)を超過 | H30: 2m(2分) | I30: long=1h,short=5m | J30: The Kube API server is burning too much error budget. | K30: The Kube API server is burning too much error budget on cluster {{ $labels.cluster }}. | L30: sum by (cluster) (apiserver_request:burnrate1h) > (14.40 * 0.01000) and on (cluster) sum by (cluster) (apiserver_request:burnrate5m) > (14.40 * 0.01000) | M30: https://runbooks.prometheus-operator.dev/runbooks/kubernetes/kubeapierrorbudgetburn | N30: マルチウィンドウ・マルチバーンレート方式の最短ウィンドウ(最も急激な消費)。同名アラートが複数段階(severity 別)で定義されている。
A31: 30 | B31: kube-apiserver-slos | C31: kube-apiserver(SLO) | D31: KubeAPIErrorBudgetBurn | E31: critical | F31: kube-apiserver の可用性 SLO(99%)に対するエラーバジェット消費速度(バーンレート) | G31: 6 時間および 30 分のバーンレートが共に 6 倍(エラー率 6%)を超過 | H31: 15m(15分) | I31: long=6h,short=30m | J31: The Kube API server is burning too much error budget. | K31: The Kube API server is burning too much error budget on cluster {{ $labels.cluster }}. | L31: sum by (cluster) (apiserver_request:burnrate6h) > (6.00 * 0.01000) and on (cluster) sum by (cluster) (apiserver_request:burnrate30m) > (6.00 * 0.01000) | M31: https://runbooks.prometheus-operator.dev/runbooks/kubernetes/kubeapierrorbudgetburn | N31: 同名アラートが複数段階(severity 別)で定義されている。
A32: 31 | B32: kube-apiserver-slos | C32: kube-apiserver(SLO) | D32: KubeAPIErrorBudgetBurn | E32: warning | F32: kube-apiserver の可用性 SLO(99%)に対するエラーバジェット消費速度(バーンレート) | G32: 1 日および 2 時間のバーンレートが共に 3 倍(エラー率 3%)を超過 | H32: 1h(1時間) | I32: long=1d,short=2h | J32: The Kube API server is burning too much error budget. | K32: The Kube API server is burning too much error budget on cluster {{ $labels.cluster }}. | L32: sum by (cluster) (apiserver_request:burnrate1d) > (3.00 * 0.01000) and on (cluster) sum by (cluster) (apiserver_request:burnrate2h) > (3.00 * 0.01000) | M32: https://runbooks.prometheus-operator.dev/runbooks/kubernetes/kubeapierrorbudgetburn | N32: 同名アラートが複数段階(severity 別)で定義されている。
A33: 32 | B33: kube-apiserver-slos | C33: kube-apiserver(SLO) | D33: KubeAPIErrorBudgetBurn | E33: warning | F33: kube-apiserver の可用性 SLO(99%)に対するエラーバジェット消費速度(バーンレート) | G33: 3 日および 6 時間のバーンレートが共に 1 倍(エラー率 1%)を超過 | H33: 3h(3時間) | I33: long=3d,short=6h | J33: The Kube API server is burning too much error budget. | K33: The Kube API server is burning too much error budget on cluster {{ $labels.cluster }}. | L33: sum by (cluster) (apiserver_request:burnrate3d) > (1.00 * 0.01000) and on (cluster) sum by (cluster) (apiserver_request:burnrate6h) > (1.00 * 0.01000) | M33: https://runbooks.prometheus-operator.dev/runbooks/kubernetes/kubeapierrorbudgetburn | N33: 最長ウィンドウ(緩やかな消費)。同名アラートが複数段階(severity 別)で定義されている。
A34: 33 | B34: kube-state-metrics | C34: kube-state-metrics | D34: KubeStateMetricsListErrors | E34: critical | F34: kube-state-metrics の list 操作エラー率 | G34: 直近 5 分間の list 操作エラー率が 1% を超過 | H34: 15m(15分) | J34: kube-state-metrics is experiencing errors in list operations. | K34: kube-state-metrics is experiencing errors at an elevated rate in list operations. This is likely causing it to not be able to expose metrics about Kubernetes objects correctly or at all. | L34: (sum(rate(kube_state_metrics_list_total{job="kube-state-metrics",result="error"}[5m])) by (cluster) / sum(rate(kube_state_metrics_list_total{job="kube-state-metrics"}[5m])) by (cluster)) > 0.01 | M34: https://runbooks.prometheus-operator.dev/runbooks/kube-state-metrics/kubestatemetricslisterrors
A35: 34 | B35: kube-state-metrics | C35: kube-state-metrics | D35: KubeStateMetricsWatchErrors | E35: critical | F35: kube-state-metrics の watch 操作エラー率 | G35: 直近 5 分間の watch 操作エラー率が 1% を超過 | H35: 15m(15分) | J35: kube-state-metrics is experiencing errors in watch operations. | K35: kube-state-metrics is experiencing errors at an elevated rate in watch operations. This is likely causing it to not be able to expose metrics about Kubernetes objects correctly or at all. | L35: (sum(rate(kube_state_metrics_watch_total{job="kube-state-metrics",result="error"}[5m])) by (cluster) / sum(rate(kube_state_metrics_watch_total{job="kube-state-metrics"}[5m])) by (cluster)) > 0.01 | M35: https://runbooks.prometheus-operator.dev/runbooks/kube-state-metrics/kubestatemetricswatcherrors
A36: 35 | B36: kube-state-metrics | C36: kube-state-metrics | D36: KubeStateMetricsShardingMismatch | E36: critical | F36: kube-state-metrics シャーディング設定の整合性 | G36: シャード総数の分散(stdvar)が 0 でない(インスタンス間でシャード数設定が不一致) | H36: 15m(15分) | J36: kube-state-metrics sharding is misconfigured. | K36: kube-state-metrics pods are running with different --total-shards configuration, some Kubernetes objects may be exposed multiple times or not exposed at all. | L36: stdvar (kube_state_metrics_total_shards{job="kube-state-metrics"}) by (cluster) != 0 | M36: https://runbooks.prometheus-operator.dev/runbooks/kube-state-metrics/kubestatemetricsshardingmismatch
A37: 36 | B37: kube-state-metrics | C37: kube-state-metrics | D37: KubeStateMetricsShardsMissing | E37: critical | F37: kube-state-metrics シャードの欠落 | G37: 期待されるシャード序数の集合と実際に稼働しているシャードの集合が一致しない | H37: 15m(15分) | J37: kube-state-metrics shards are missing. | K37: kube-state-metrics shards are missing, some Kubernetes objects are not being exposed. | L37: 2^max(kube_state_metrics_total_shards{job="kube-state-metrics"}) by (cluster) - 1 - sum( 2 ^ max by (cluster, shard_ordinal) (kube_state_metrics_shard_ordinal{job="kube-state-metrics"}) ) by (cluster) != 0 | M37: https://runbooks.prometheus-operator.dev/runbooks/kube-state-metrics/kubestatemetricsshardsmissing
A38: 37 | B38: kubernetes-apps | C38: ワークロード(Pod/Deployment/StatefulSet/DaemonSet/Job/HPA/PDB) | D38: KubePodCrashLooping | E38: warning | F38: Pod コンテナのクラッシュループ | G38: 直近 5 分間でコンテナの waiting 理由が CrashLoopBackOff になっている | H38: 15m(15分) | J38: Pod is crash looping. | K38: Pod {{ $labels.namespace }}/{{ $labels.pod }} ({{ $labels.container }}) is in waiting state (reason: "CrashLoopBackOff") on cluster {{ $labels.cluster }}. | L38: max_over_time(kube_pod_container_status_waiting_reason{reason="CrashLoopBackOff", job="kube-state-metrics", namespace=~".*"}[5m]) >= 1 | M38: https://runbooks.prometheus-operator.dev/runbooks/kubernetes/kubepodcrashlooping
A39: 38 | B39: kubernetes-apps | C39: ワークロード(Pod/Deployment/StatefulSet/DaemonSet/Job/HPA/PDB) | D39: KubePodNotReady | E39: warning | F39: Pod の Ready 状態 | G39: Pod が Pending/Unknown、または Running だが Ready でない状態(Job 管理下・SchedulingGated の Pod は除外) | H39: 15m(15分) | J39: Pod has been in a non-ready state for more than 15 minutes. | K39: Pod {{ $labels.namespace }}/{{ $labels.pod }} has been in a non-ready state for longer than 15 minutes on cluster {{ $labels.cluster }}. | L39: sum by (namespace, pod, job, cluster) ( max by (namespace, pod, job, cluster) ( kube_pod_status_phase{job="kube-state-metrics", namespace=~".*", phase=~"Pending|Unknown"} or ( kube_pod_status_phase{job="kube-state-metrics", namespace=~".*", phase="Running"} == 1 and on (namespace, pod, cluster) kube_pod_status_ready{job="kube-state-metrics", namespace=~".*", condition="true"} == 0 ) ) * on (namespace, pod, cluster) group_left() topk by (namespace, pod, cluster) ( 1, max by (namespace, pod, owner_kind, cluster) (kube_pod_owner{owner_kind!="Job"}) ) ) > 0 unless on (namespace, pod, cluster) kube_pod_status_reason{job="kube-state-metrics", namespace=~".*", reason="SchedulingGated"} == 1 | M39: https://runbooks.prometheus-operator.dev/runbooks/kubernetes/kubepodnotready
A40: 39 | B40: kubernetes-apps | C40: ワークロード(Pod/Deployment/StatefulSet/DaemonSet/Job/HPA/PDB) | D40: KubeDeploymentGenerationMismatch | E40: warning | F40: Deployment の世代(generation)整合性 | G40: observed_generation != metadata_generation(コントローラが最新の spec を反映できていない) | H40: 15m(15分) | J40: Deployment generation mismatch due to possible roll-back | K40: Deployment generation for {{ $labels.namespace }}/{{ $labels.deployment }} does not match, this indicates that the Deployment has failed but has not been rolled back on cluster {{ $labels.cluster }}. | L40: kube_deployment_status_observed_generation{job="kube-state-metrics", namespace=~".*"} != kube_deployment_metadata_generation{job="kube-state-metrics", namespace=~".*"} | M40: https://runbooks.prometheus-operator.dev/runbooks/kubernetes/kubedeploymentgenerationmismatch
...

Sheet サマリ
A1: 監視項目サマリ(「監視項目一覧」シートから数式で集計)
A3: 重要度 (severity) | B3: 件数
A4: critical | B4: =COUNTIF('監視項目一覧'!$E$2:$E$156,"critical")
A5: warning | B5: =COUNTIF('監視項目一覧'!$E$2:$E$156,"warning")
A6: info | B6: =COUNTIF('監視項目一覧'!$E$2:$E$156,"info")
A7: none | B7: =COUNTIF('監視項目一覧'!$E$2:$E$156,"none")
A8: 合計 | B8: =SUM(B4:B7)
A11: カテゴリ(ルールグループ) | B11: critical | C11: warning | D11: info | E11: none | F11: 合計
A12: alertmanager.rules | B12: =COUNTIFS('監視項目一覧'!$B$2:$B$156,$A12,'監視項目一覧'!$E$2:$E$156,"critical") | C12: =COUNTIFS('監視項目一覧'!$B$2:$B$156,$A12,'監視項目一覧'!$E$2:$E$156,"warning") | D12: =COUNTIFS('監視項目一覧'!$B$2:$B$156,$A12,'監視項目一覧'!$E$2:$E$156,"info") | E12: =COUNTIFS('監視項目一覧'!$B$2:$B$156,$A12,'監視項目一覧'!$E$2:$E$156,"none") | F12: =SUM(B12:E12)
A13: config-reloaders | B13: =COUNTIFS('監視項目一覧'!$B$2:$B$156,$A13,'監視項目一覧'!$E$2:$E$156,"critical") | C13: =COUNTIFS('監視項目一覧'!$B$2:$B$156,$A13,'監視項目一覧'!$E$2:$E$156,"warning") | D13: =COUNTIFS('監視項目一覧'!$B$2:$B$156,$A13,'監視項目一覧'!$E$2:$E$156,"info") | E13: =COUNTIFS('監視項目一覧'!$B$2:$B$156,$A13,'監視項目一覧'!$E$2:$E$156,"none") | F13: =SUM(B13:E13)
A14: etcd | B14: =COUNTIFS('監視項目一覧'!$B$2:$B$156,$A14,'監視項目一覧'!$E$2:$E$156,"critical") | C14: =COUNTIFS('監視項目一覧'!$B$2:$B$156,$A14,'監視項目一覧'!$E$2:$E$156,"warning") | D14: =COUNTIFS('監視項目一覧'!$B$2:$B$156,$A14,'監視項目一覧'!$E$2:$E$156,"info") | E14: =COUNTIFS('監視項目一覧'!$B$2:$B$156,$A14,'監視項目一覧'!$E$2:$E$156,"none") | F14: =SUM(B14:E14)
A15: general.rules | B15: =COUNTIFS('監視項目一覧'!$B$2:$B$156,$A15,'監視項目一覧'!$E$2:$E$156,"critical") | C15: =COUNTIFS('監視項目一覧'!$B$2:$B$156,$A15,'監視項目一覧'!$E$2:$E$156,"warning") | D15: =COUNTIFS('監視項目一覧'!$B$2:$B$156,$A15,'監視項目一覧'!$E$2:$E$156,"info") | E15: =COUNTIFS('監視項目一覧'!$B$2:$B$156,$A15,'監視項目一覧'!$E$2:$E$156,"none") | F15: =SUM(B15:E15)
A16: kube-apiserver-slos | B16: =COUNTIFS('監視項目一覧'!$B$2:$B$156,$A16,'監視項目一覧'!$E$2:$E$156,"critical") | C16: =COUNTIFS('監視項目一覧'!$B$2:$B$156,$A16,'監視項目一覧'!$E$2:$E$156,"warning") | D16: =COUNTIFS('監視項目一覧'!$B$2:$B$156,$A16,'監視項目一覧'!$E$2:$E$156,"info") | E16: =COUNTIFS('監視項目一覧'!$B$2:$B$156,$A16,'監視項目一覧'!$E$2:$E$156,"none") | F16: =SUM(B16:E16)
A17: kube-state-metrics | B17: =COUNTIFS('監視項目一覧'!$B$2:$B$156,$A17,'監視項目一覧'!$E$2:$E$156,"critical") | C17: =COUNTIFS('監視項目一覧'!$B$2:$B$156,$A17,'監視項目一覧'!$E$2:$E$156,"warning") | D17: =COUNTIFS('監視項目一覧'!$B$2:$B$156,$A17,'監視項目一覧'!$E$2:$E$156,"info") | E17: =COUNTIFS('監視項目一覧'!$B$2:$B$156,$A17,'監視項目一覧'!$E$2:$E$156,"none") | F17: =SUM(B17:E17)
A18: kubernetes-apps | B18: =COUNTIFS('監視項目一覧'!$B$2:$B$156,$A18,'監視項目一覧'!$E$2:$E$156,"critical") | C18: =COUNTIFS('監視項目一覧'!$B$2:$B$156,$A18,'監視項目一覧'!$E$2:$E$156,"warning") | D18: =COUNTIFS('監視項目一覧'!$B$2:$B$156,$A18,'監視項目一覧'!$E$2:$E$156,"info") | E18: =COUNTIFS('監視項目一覧'!$B$2:$B$156,$A18,'監視項目一覧'!$E$2:$E$156,"none") | F18: =SUM(B18:E18)
A19: kubernetes-resources | B19: =COUNTIFS('監視項目一覧'!$B$2:$B$156,$A19,'監視項目一覧'!$E$2:$E$156,"critical") | C19: =COUNTIFS('監視項目一覧'!$B$2:$B$156,$A19,'監視項目一覧'!$E$2:$E$156,"warning") | D19: =COUNTIFS('監視項目一覧'!$B$2:$B$156,$A19,'監視項目一覧'!$E$2:$E$156,"info") | E19: =COUNTIFS('監視項目一覧'!$B$2:$B$156,$A19,'監視項目一覧'!$E$2:$E$156,"none") | F19: =SUM(B19:E19)
A20: kubernetes-storage | B20: =COUNTIFS('監視項目一覧'!$B$2:$B$156,$A20,'監視項目一覧'!$E$2:$E$156,"critical") | C20: =COUNTIFS('監視項目一覧'!$B$2:$B$156,$A20,'監視項目一覧'!$E$2:$E$156,"warning") | D20: =COUNTIFS('監視項目一覧'!$B$2:$B$156,$A20,'監視項目一覧'!$E$2:$E$156,"info") | E20: =COUNTIFS('監視項目一覧'!$B$2:$B$156,$A20,'監視項目一覧'!$E$2:$E$156,"none") | F20: =SUM(B20:E20)
A21: kubernetes-system | B21: =COUNTIFS('監視項目一覧'!$B$2:$B$156,$A21,'監視項目一覧'!$E$2:$E$156,"critical") | C21: =COUNTIFS('監視項目一覧'!$B$2:$B$156,$A21,'監視項目一覧'!$E$2:$E$156,"warning") | D21: =COUNTIFS('監視項目一覧'!$B$2:$B$156,$A21,'監視項目一覧'!$E$2:$E$156,"info") | E21: =COUNTIFS('監視項目一覧'!$B$2:$B$156,$A21,'監視項目一覧'!$E$2:$E$156,"none") | F21: =SUM(B21:E21)
A22: kubernetes-system-apiserver | B22: =COUNTIFS('監視項目一覧'!$B$2:$B$156,$A22,'監視項目一覧'!$E$2:$E$156,"critical") | C22: =COUNTIFS('監視項目一覧'!$B$2:$B$156,$A22,'監視項目一覧'!$E$2:$E$156,"warning") | D22: =COUNTIFS('監視項目一覧'!$B$2:$B$156,$A22,'監視項目一覧'!$E$2:$E$156,"info") | E22: =COUNTIFS('監視項目一覧'!$B$2:$B$156,$A22,'監視項目一覧'!$E$2:$E$156,"none") | F22: =SUM(B22:E22)
A23: kubernetes-system-controller-manager | B23: =COUNTIFS('監視項目一覧'!$B$2:$B$156,$A23,'監視項目一覧'!$E$2:$E$156,"critical") | C23: =COUNTIFS('監視項目一覧'!$B$2:$B$156,$A23,'監視項目一覧'!$E$2:$E$156,"warning") | D23: =COUNTIFS('監視項目一覧'!$B$2:$B$156,$A23,'監視項目一覧'!$E$2:$E$156,"info") | E23: =COUNTIFS('監視項目一覧'!$B$2:$B$156,$A23,'監視項目一覧'!$E$2:$E$156,"none") | F23: =SUM(B23:E23)
... A30: prometheus-operator | B30: =COUNTIFS('監視項目一覧'!$B$2:$B$156,$A30,'監視項目一覧'!$E$2:$E$156,"critical") | C30: =COUNTIFS('監視項目一覧'!$B$2:$B$156,$A30,'監視項目一覧'!$E$2:$E$156,"warning") | D30: =COUNTIFS('監視項目一覧'!$B$2:$B$156,$A30,'監視項目一覧'!$E$2:$E$156,"info") | E30: =COUNTIFS('監視項目一覧'!$B$2:$B$156,$A30,'監視項目一覧'!$E$2:$E$156,"none") | F30: =SUM(B30:E30)
A31: 合計 | B31: =SUM(B12:B30) | C31: =SUM(C12:C30) | D31: =SUM(D12:D30) | E31: =SUM(E12:E30) | F31: =SUM(F12:F30)
A34: 継続時間 (for) | B34: 件数
A35: 即時(for 未設定) | B35: =COUNTIF('監視項目一覧'!$H$2:$H$156,"即時(for 未設定)")
A36: 0s(即時) | B36: =COUNTIF('監視項目一覧'!$H$2:$H$156,"0s(即時)")
A37: 1m(1分) | B37: =COUNTIF('監視項目一覧'!$H$2:$H$156,"1m(1分)")
A38: 2m(2分) | B38: =COUNTIF('監視項目一覧'!$H$2:$H$156,"2m(2分)")
A39: 3m(3分) | B39: =COUNTIF('監視項目一覧'!$H$2:$H$156,"3m(3分)")
A40: 5m(5分) | B40: =COUNTIF('監視項目一覧'!$H$2:$H$156,"5m(5分)")
A41: 10m(10分) | B41: =COUNTIF('監視項目一覧'!$H$2:$H$156,"10m(10分)")
A42: 15m(15分) | B42: =COUNTIF('監視項目一覧'!$H$2:$H$156,"15m(15分)")
A43: 20m(20分) | B43: =COUNTIF('監視項目一覧'!$H$2:$H$156,"20m(20分)")
A44: 30m(30分) | B44: =COUNTIF('監視項目一覧'!$H$2:$H$156,"30m(30分)")
A45: 1h(1時間) | B45: =COUNTIF('監視項目一覧'!$H$2:$H$156,"1h(1時間)")
A46: 3h(3時間) | B46: =COUNTIF('監視項目一覧'!$H$2:$H$156,"3h(3時間)")
A47: 4h(4時間) | B47: =COUNTIF('監視項目一覧'!$H$2:$H$156,"4h(4時間)")
A48: 合計 | B48: =SUM(B35:B47)

Sheet 凡例・前提
A1: 1. 出典・生成情報
A2: 入力ファイル | B2: kubectl get prometheusrules -n monitoring -o yaml の出力(docs/source/alert_definition.yaml)
A3: Helm chart | B3: kube-prometheus-stack-88.6.3
A4: namespace | B4: monitoring
A5: リソース作成日時(UTC) | B5: 2026-09-03T02:22:51Z
A6: PrometheusRule 数 | B6: 35 件 / ルールグループ 35 個
A7: アラートルール数 | B7: 155 件(本一覧の対象)
A8: 記録ルール数 | B8: 94 件(record: ルール。アラートではないため本一覧の対象外)
A9: 生成スクリプト | B9: tools/build_alert_sheet.py(日本語訳はスクリプト内の辞書で管理)
A11: 2. 重要度(severity)の目安
A12: critical | B12: サービス影響が出ている、または差し迫っている。即時対応が必要。
A13: warning | B13: 放置するとサービス影響につながる可能性がある。営業時間内に確認・対応。
A14: info | B14: 情報通知。単独では対応不要だが、他アラートと併発した際の調査材料。標準構成では InfoInhibitor により warning/critical 併発時は抑止される。
A15: none | B15: 通知用ではない制御用アラート(Watchdog: 死活確認、InfoInhibitor: 抑止制御)。Alertmanager では null receiver に送るのが標準。
A17: 3. 列の読み方
A18: 発報条件・閾値 | B18: PromQL(expr)を日本語で要約したもの。正確な条件は PromQL 列を正とする。
A19: 継続時間 (for) | B19: 「発報条件・閾値」の状態が for に指定した時間継続した時点で firing(発報)となる。for が未設定または 0s の場合は条件成立と同時に発報する(pending 状態を経ない)。
A20: 追加ラベル | B20: severity 以外にルールが付与するラベル。KubeAPIErrorBudgetBurn の long/short(評価ウィンドウ)など、同名アラートの区別に使う。
A21: 同名アラート | B21: 同じアラート名が複数行ある場合は、閾値の異なる段階アラート(例: warning=5% 未満 / critical=3% 未満)。1 定義 = 1 行として全件を掲載している。
A22: Summary / Description(原文) | B22: ルール定義の annotations をそのまま転記。{{ $labels.xxx }} / {{ $value }} は発報時に実値へ置換されるテンプレート。
A24: 4. 通知経路に関する注記(Alertmanager)
A25: 基本の流れ | B25: Prometheus が firing と判定したアラートはすべて Alertmanager に送信される。実際にメール等で通知されるかは Alertmanager 側の設定(route / receivers / inhibit_rules)で決まる。
A26: route と receiver | B26: Alertmanager の route ツリーで、アラートのラベル(severity、namespace、alertname 等)にマッチした receiver に配送される。その receiver に email_configs が設定されていれば、その宛先にメールが送られる。マッチしなければ既定 receiver に落ちる。kube-prometheus-stack の初期値では既定 receiver が 'null'(どこにも通知しない)。
A27: 通知されないアラート | B27: Watchdog(severity=none)は null receiver へ送る route が初期値で入っている。InfoInhibitor も null receiver に送る前提の設計。この 2 件は「一覧にはあるがメールは来ない」ことが正常。
A28: 抑止(inhibit) | B28: 初期値の inhibit_rules により、同一対象で critical が firing 中は warning/info を、warning が firing 中は info を抑止する。また InfoInhibitor 発報中は同 namespace の info を抑止する。抑止されたアラートは通知されない。
A29: グループ化 | B29: group_by / group_wait / group_interval / repeat_interval により複数アラートが 1 通のメールにまとめられる。一覧の 1 行が必ず 1 通のメールに対応するわけではない。
A30: 実設定の確認方法 | B30: kubectl -n monitoring get secret alertmanager-monitoring-kube-prometheus-alertmanager-generated -o jsonpath='{.data.alertmanager\.yaml\.gz}' | base64 -d | gunzip または Helm values の alertmanager.config / AlertmanagerConfig CR を参照。
